Workbook

Sheet Introduction
C10: 1 | D10: Workload Information | E10: Use this worksheet to enter information about the Workload being assessed. Required Action: 1. Ensure that all required fields are filled with the necessary information.
C11: 2 | D11: Workload Inventory | E11: Use this worksheet to see all resources that are part of the workload. This includes all in-scope resources, including resource groups and subscriptions. No Required Action.
C12: 3 | D12: Analysis Planning | E12: Use this worksheet to coordinate your validation process, especially when collaborating with others. You can assign ownership for each Resource Type, view the number of resources per Resource Type, the number of impacted resources, and more. Required Action: 1. Ensure that all categories are fully validated and have a "Reviewed" status before running the Reports Generator script.
C13: 4 | D13: Impacted Resources and Recommentations | E13: This worksheet shows all in-scope impacted resources, that is, resources not following Microsoft recommendations for resiliency and reliability. Required Actions: Ensure all recommendations and resources associated with the following categories are reviewed: 1. Recommendation does not have automated validation. 2. ResourceType not available in APRL/Advisor. 3. Well-Architected Framework. 4. Azure Service Health - Service Retirements.
C14: 5 | D14: Platform Issues | E14: This worksheet shows all Azure Platform and Service Issues that are associated with the resources used by the workload. Required Actions: 1. Review the affected Azure Service, Date, Impact and Recommendations for each of Platform Issue. 2. For relevant Platform Issues (that really affected the workload), read the recommendations in field "What customers can do to avoid being affected", go to the Impacted Resources" worksheet, search for equivalent recommendations to associate with the Tracking ID of the Service Issue, or crrate a new recommendation(s) and associate with the necessary resource(s), or entire Subscription.
C15: 6 | D15: Support Requests | E15: This worksheet shows all Support Tickets opened by users for the Subscriptions associated with the workload. Required Actions: 1. Review the resolution and recommendations from Microsoft Support for each of the Support Tickets 2. For relevant Support Tickets, using the recommendations from the Microsoft Support team, add the recommendations to the "Recommendations and Impacted Resources" and associate with the necessary resource(s), or entire workload. Adapt the Title and all Recommendation fields if necessary to fit the 100 (Title) and 300 (Long Description) max characters.

Sheet 1.WorkloadInformation
A1: cc
B6: Information | C6: . | D6: Workload Data | F6: Example:
B7: Workload Name | C7: Required | F7: Contoso Hotels
B8: Azure Cloud | C8: Required | F8: Commercial / Government
B9: Primary Region | C9: Required | F9: EastUS
B10: Secondary/DR Region | C10: Required | F10: WestUS3
B11: Criticality for the Business | C11: Required | F11: Critical / High / Medium / Low
B12: Availability/DR Design Pattern | C12: Required | F12: Active-Active / Active-Passive (Cold / Warm Standy)
B13: SLA | C13: Required | F13: 99.00 / 99.90 / 99.95
B14: RPO | C14: Required | F14: Minutes / Hours
B15: RTO | C15: Required | F15: Minutes / Hours
B16: Top 1 Challenge/Pain point | C16: Optional
B17: Top 2 Challenge/Pain point | C17: Optional
B18: Top 3 Challenge/Pain point | C18: Optional

Sheet 2.WorkloadInventory
A12: id | B12: name | C12: type | D12: tenantId | E12: kind | F12: location | G12: resourceGroup | H12: subscriptionId | I12: managedBy | J12: sku | K12: plan | L12: zones
A13: /subscriptions/508d4c26-18a2-4b58-b83d-5535758910b0/resourceGroups/ADTSource/providers/Microsoft.AzureDataTransfer/connections/ADTSource0 | B13: ADTSource0 | C13: microsoft.azuredatatransfer/connections | D13: da667b97-c1f7-494e-b7ba-172131cd40d9 | F13: eastus | G13: adtsource | H13: 508d4c26-18a2-4b58-b83d-5535758910b0
A14: /subscriptions/508d4c26-18a2-4b58-b83d-5535758910b0/resourceGroups/Default-ActivityLogAlerts/providers/Microsoft.Insights/actiongroups/AGOwner | B14: AGOwner | C14: microsoft.insights/actiongroups | D14: da667b97-c1f7-494e-b7ba-172131cd40d9 | F14: global | G14: default-activitylogalerts | H14: 508d4c26-18a2-4b58-b83d-5535758910b0
A15: /subscriptions/508d4c26-18a2-4b58-b83d-5535758910b0/resourceGroups/mcapsgovernance/providers/Microsoft.EventGrid/systemTopics/mcapsb83d5535758910b0-84fe27b9-60c6-44e8-a98f-9de1efe22453 | B15: mcapsb83d5535758910b0-84fe27b9-60c6-44e8-a98f-9de1efe22453 | C15: microsoft.eventgrid/systemtopics | D15: da667b97-c1f7-494e-b7ba-172131cd40d9 | F15: westus2 | G15: mcapsgovernance | H15: 508d4c26-18a2-4b58-b83d-5535758910b0
A16: /subscriptions/508d4c26-18a2-4b58-b83d-5535758910b0/resourceGroups/McapsGovernance/providers/Microsoft.Storage/storageAccounts/mcapsb83d5535758910b0 | B16: mcapsb83d5535758910b0 | C16: microsoft.storage/storageaccounts | D16: da667b97-c1f7-494e-b7ba-172131cd40d9 | F16: westus2 | G16: mcapsgovernance | H16: 508d4c26-18a2-4b58-b83d-5535758910b0
A17: /subscriptions/508d4c26-18a2-4b58-b83d-5535758910b0/resourceGroups/monitoring/providers/Microsoft.EventGrid/systemTopics/pauharritest0sa-96613d94-50ef-4fe8-838b-cab034350066 | B17: pauharritest0sa-96613d94-50ef-4fe8-838b-cab034350066 | C17: microsoft.eventgrid/systemtopics | D17: da667b97-c1f7-494e-b7ba-172131cd40d9 | F17: eastus | G17: monitoring | H17: 508d4c26-18a2-4b58-b83d-5535758910b0
A18: /subscriptions/508d4c26-18a2-4b58-b83d-5535758910b0/resourceGroups/monitoring/providers/Microsoft.Insights/dataCollectionEndpoints/dce-mytestvm0-centralus-cfg | B18: dce-mytestvm0-centralus-cfg | C18: microsoft.insights/datacollectionendpoints | D18: da667b97-c1f7-494e-b7ba-172131cd40d9 | F18: centralus | G18: monitoring | H18: 508d4c26-18a2-4b58-b83d-5535758910b0
A19: /subscriptions/508d4c26-18a2-4b58-b83d-5535758910b0/resourceGroups/monitoring/providers/Microsoft.Insights/dataCollectionEndpoints/dce-mytestvm0-eastus | B19: dce-mytestvm0-eastus | C19: microsoft.insights/datacollectionendpoints | D19: da667b97-c1f7-494e-b7ba-172131cd40d9 | F19: eastus | G19: monitoring | H19: 508d4c26-18a2-4b58-b83d-5535758910b0
A20: /subscriptions/508d4c26-18a2-4b58-b83d-5535758910b0/resourceGroups/monitoring/providers/Microsoft.Insights/dataCollectionRules/ct-dcr-188645704-12406056 | B20: ct-dcr-188645704-12406056 | C20: microsoft.insights/datacollectionrules | D20: da667b97-c1f7-494e-b7ba-172131cd40d9 | F20: eastus | G20: monitoring | H20: 508d4c26-18a2-4b58-b83d-5535758910b0
A21: /subscriptions/508d4c26-18a2-4b58-b83d-5535758910b0/resourceGroups/monitoring/providers/Microsoft.Insights/privateLinkScopes/ampls-atofa | B21: ampls-atofa | C21: microsoft.insights/privatelinkscopes | D21: da667b97-c1f7-494e-b7ba-172131cd40d9 | F21: global | G21: monitoring | H21: 508d4c26-18a2-4b58-b83d-5535758910b0
A22: /subscriptions/508d4c26-18a2-4b58-b83d-5535758910b0/resourceGroups/monitoring/providers/Microsoft.OperationalInsights/workspaces/monitoring-law | B22: monitoring-law | C22: microsoft.operationalinsights/workspaces | D22: da667b97-c1f7-494e-b7ba-172131cd40d9 | F22: eastus | G22: monitoring | H22: 508d4c26-18a2-4b58-b83d-5535758910b0
A23: /subscriptions/508d4c26-18a2-4b58-b83d-5535758910b0/resourceGroups/monitoring/providers/Microsoft.OperationsManagement/solutions/ChangeTracking(monitoring-law) | B23: ChangeTracking(monitoring-law) | C23: microsoft.operationsmanagement/solutions | D23: da667b97-c1f7-494e-b7ba-172131cd40d9 | F23: eastus | G23: monitoring | H23: 508d4c26-18a2-4b58-b83d-5535758910b0
A24: /subscriptions/508d4c26-18a2-4b58-b83d-5535758910b0/resourceGroups/monitoring/providers/Microsoft.OperationsManagement/solutions/SecurityInsights(monitoring-law) | B24: SecurityInsights(monitoring-law) | C24: microsoft.operationsmanagement/solutions | D24: da667b97-c1f7-494e-b7ba-172131cd40d9 | F24: eastus | G24: monitoring | H24: 508d4c26-18a2-4b58-b83d-5535758910b0
... A42: /subscriptions/508d4c26-18a2-4b58-b83d-5535758910b0/resourceGroups/tenantNSGSub1/providers/Microsoft.Network/networkSecurityGroups/tenantNSGSub1 | B42: tenantNSGSub1 | C42: microsoft.network/networksecuritygroups | D42: da667b97-c1f7-494e-b7ba-172131cd40d9 | F42: centralus | G42: tenantnsgsub1 | H42: 508d4c26-18a2-4b58-b83d-5535758910b0

Sheet 3.AnalysisPlanning
A1: =COUNTIFS('4.ImpactedResourcesAnalysis'!A:A,"Reviewed") -> 28
A2: =COUNTIFS('4.ImpactedResourcesAnalysis'!A:A,"<>Reviewed",'4.ImpactedResourcesAnalysis'!A:A,"<>")-1 -> 61
A3: =COUNTIFS('5.PlatformIssuesAnalysis'!A:A,"Reviewed") -> 0
A4: =COUNTIFS('5.PlatformIssuesAnalysis'!A:A,"<>Reviewed",'5.PlatformIssuesAnalysis'!A:A,"<>")-1 -> 1
A5: =COUNTIFS('6.SupportRequestsAnalysis'!A:A,"Reviewed") -> 0
A6: =COUNTIFS('6.SupportRequestsAnalysis'!A:A,"<>Reviewed",'6.SupportRequestsAnalysis'!A:A,"<>")-1 -> 1
A10: Category | B10: Resource Type | C10: Number of Resources | D10: Impacted Resources | E10: Has Recommendations in APRL/Advisor | F10: Assessment Owner | G10: Assessment Status | H10: Notes
A11: Impacted Resources | B11: microsoft.cognitiveservices/accounts | C11: {=COUNTA(_xlfn.UNIQUE(_xlfn.VSTACK(_xlfn._xlws.FILTER('2.WorkloadInventory'!A:A, '2.WorkloadInventory'!C:C = TableTypes8[[#This Row],[Resource Type]]), _xlfn._xlws.FILTER('2.WorkloadInventory'!A:A, '2.WorkloadInventory'!C:C = TableTypes8[[#This Row],[Resource Type]]))))} -> 2 | D11: {=IF(COUNTIF('4.ImpactedResourcesAnalysis'!C:C, TableTypes8[[#This Row],[Resource Type]])=0, 0, COUNTA(_xlfn.UNIQUE(_xlfn._xlws.FILTER('4.ImpactedResourcesAnalysis'!H:H, ('4.ImpactedResourcesAnalysis'!C:C=TableTypes8[[#This Row],[Resource Type]]) * ('4.ImpactedResourcesAnalysis'!H:H<>"Get ResourceID from Azure Portal")))))} -> 2 | E11: Yes | G11: =IF(OR(AND(TableTypes8[[#This Row],[Category]]="Support Requests", COUNTIFS('6.SupportRequestsAnalysis'!A:A, "<>Reviewed")=0),AND(TableTypes8[[#This Row],[Category]]="Platform Issues", COUNTIFS('5.PlatformIssuesAnalysis'!A:A, "<>Reviewed")=0),AND(TableTypes8[[#This Row],[Category]]="Impacted Resources", COUNTIFS('4.ImpactedResourcesAnalysis'!A:A, "<>Reviewed", '4.ImpactedResourcesAnalysis'!C:C, TableTypes8[[#This Row],[Resource Type]], '4.ImpactedResourcesAnalysis'!O:O, "<>Low")=0)), "Reviewed", "Pending") -> Pending
A12: Impacted Resources | B12: Microsoft.DocumentDB/databaseAccounts | C12: {=COUNTA(_xlfn.UNIQUE(_xlfn.VSTACK(_xlfn._xlws.FILTER('2.WorkloadInventory'!A:A, '2.WorkloadInventory'!C:C = TableTypes8[[#This Row],[Resource Type]]), _xlfn._xlws.FILTER('2.WorkloadInventory'!A:A, '2.WorkloadInventory'!C:C = TableTypes8[[#This Row],[Resource Type]]))))} -> 1 | D12: {=IF(COUNTIF('4.ImpactedResourcesAnalysis'!C:C, TableTypes8[[#This Row],[Resource Type]])=0, 0, COUNTA(_xlfn.UNIQUE(_xlfn._xlws.FILTER('4.ImpactedResourcesAnalysis'!H:H, ('4.ImpactedResourcesAnalysis'!C:C=TableTypes8[[#This Row],[Resource Type]]) * ('4.ImpactedResourcesAnalysis'!H:H<>"Get ResourceID from Azure Portal")))))} -> 1 | E12: Yes | G12: =IF(OR(AND(TableTypes8[[#This Row],[Category]]="Support Requests", COUNTIFS('6.SupportRequestsAnalysis'!A:A, "<>Reviewed")=0),AND(TableTypes8[[#This Row],[Category]]="Platform Issues", COUNTIFS('5.PlatformIssuesAnalysis'!A:A, "<>Reviewed")=0),AND(TableTypes8[[#This Row],[Category]]="Impacted Resources", COUNTIFS('4.ImpactedResourcesAnalysis'!A:A, "<>Reviewed", '4.ImpactedResourcesAnalysis'!C:C, TableTypes8[[#This Row],[Resource Type]], '4.ImpactedResourcesAnalysis'!O:O, "<>Low")=0)), "Reviewed", "Pending") -> Pending
A13: Impacted Resources | B13: microsoft.eventgrid/systemtopics | C13: {=COUNTA(_xlfn.UNIQUE(_xlfn.VSTACK(_xlfn._xlws.FILTER('2.WorkloadInventory'!A:A, '2.WorkloadInventory'!C:C = TableTypes8[[#This Row],[Resource Type]]), _xlfn._xlws.FILTER('2.WorkloadInventory'!A:A, '2.WorkloadInventory'!C:C = TableTypes8[[#This Row],[Resource Type]]))))} -> 3 | D13: {=IF(COUNTIF('4.ImpactedResourcesAnalysis'!C:C, TableTypes8[[#This Row],[Resource Type]])=0, 0, COUNTA(_xlfn.UNIQUE(_xlfn._xlws.FILTER('4.ImpactedResourcesAnalysis'!H:H, ('4.ImpactedResourcesAnalysis'!C:C=TableTypes8[[#This Row],[Resource Type]]) * ('4.ImpactedResourcesAnalysis'!H:H<>"Get ResourceID from Azure Portal")))))} -> 3 | E13: No | G13: =IF(OR(AND(TableTypes8[[#This Row],[Category]]="Support Requests", COUNTIFS('6.SupportRequestsAnalysis'!A:A, "<>Reviewed")=0),AND(TableTypes8[[#This Row],[Category]]="Platform Issues", COUNTIFS('5.PlatformIssuesAnalysis'!A:A, "<>Reviewed")=0),AND(TableTypes8[[#This Row],[Category]]="Impacted Resources", COUNTIFS('4.ImpactedResourcesAnalysis'!A:A, "<>Reviewed", '4.ImpactedResourcesAnalysis'!C:C, TableTypes8[[#This Row],[Resource Type]], '4.ImpactedResourcesAnalysis'!O:O, "<>Low")=0)), "Reviewed", "Pending") -> Reviewed
A14: Impacted Resources | B14: Microsoft.Network/networkSecurityGroups | C14: {=COUNTA(_xlfn.UNIQUE(_xlfn.VSTACK(_xlfn._xlws.FILTER('2.WorkloadInventory'!A:A, '2.WorkloadInventory'!C:C = TableTypes8[[#This Row],[Resource Type]]), _xlfn._xlws.FILTER('2.WorkloadInventory'!A:A, '2.WorkloadInventory'!C:C = TableTypes8[[#This Row],[Resource Type]]))))} -> 2 | D14: {=IF(COUNTIF('4.ImpactedResourcesAnalysis'!C:C, TableTypes8[[#This Row],[Resource Type]])=0, 0, COUNTA(_xlfn.UNIQUE(_xlfn._xlws.FILTER('4.ImpactedResourcesAnalysis'!H:H, ('4.ImpactedResourcesAnalysis'!C:C=TableTypes8[[#This Row],[Resource Type]]) * ('4.ImpactedResourcesAnalysis'!H:H<>"Get ResourceID from Azure Portal")))))} -> 2 | E14: Yes | G14: =IF(OR(AND(TableTypes8[[#This Row],[Category]]="Support Requests", COUNTIFS('6.SupportRequestsAnalysis'!A:A, "<>Reviewed")=0),AND(TableTypes8[[#This Row],[Category]]="Platform Issues", COUNTIFS('5.PlatformIssuesAnalysis'!A:A, "<>Reviewed")=0),AND(TableTypes8[[#This Row],[Category]]="Impacted Resources", COUNTIFS('4.ImpactedResourcesAnalysis'!A:A, "<>Reviewed", '4.ImpactedResourcesAnalysis'!C:C, TableTypes8[[#This Row],[Resource Type]], '4.ImpactedResourcesAnalysis'!O:O, "<>Low")=0)), "Reviewed", "Pending") -> Pending
A15: Impacted Resources | B15: microsoft.network/networkwatchers | C15: {=COUNTA(_xlfn.UNIQUE(_xlfn.VSTACK(_xlfn._xlws.FILTER('2.WorkloadInventory'!A:A, '2.WorkloadInventory'!C:C = TableTypes8[[#This Row],[Resource Type]]), _xlfn._xlws.FILTER('2.WorkloadInventory'!A:A, '2.WorkloadInventory'!C:C = TableTypes8[[#This Row],[Resource Type]]))))} -> 2 | D15: {=IF(COUNTIF('4.ImpactedResourcesAnalysis'!C:C, TableTypes8[[#This Row],[Resource Type]])=0, 0, COUNTA(_xlfn.UNIQUE(_xlfn._xlws.FILTER('4.ImpactedResourcesAnalysis'!H:H, ('4.ImpactedResourcesAnalysis'!C:C=TableTypes8[[#This Row],[Resource Type]]) * ('4.ImpactedResourcesAnalysis'!H:H<>"Get ResourceID from Azure Portal")))))} -> 2 | E15: Yes | G15: =IF(OR(AND(TableTypes8[[#This Row],[Category]]="Support Requests", COUNTIFS('6.SupportRequestsAnalysis'!A:A, "<>Reviewed")=0),AND(TableTypes8[[#This Row],[Category]]="Platform Issues", COUNTIFS('5.PlatformIssuesAnalysis'!A:A, "<>Reviewed")=0),AND(TableTypes8[[#This Row],[Category]]="Impacted Resources", COUNTIFS('4.ImpactedResourcesAnalysis'!A:A, "<>Reviewed", '4.ImpactedResourcesAnalysis'!C:C, TableTypes8[[#This Row],[Resource Type]], '4.ImpactedResourcesAnalysis'!O:O, "<>Low")=0)), "Reviewed", "Pending") -> Pending
A16: Impacted Resources | B16: Microsoft.Network/virtualNetworks | C16: {=COUNTA(_xlfn.UNIQUE(_xlfn.VSTACK(_xlfn._xlws.FILTER('2.WorkloadInventory'!A:A, '2.WorkloadInventory'!C:C = TableTypes8[[#This Row],[Resource Type]]), _xlfn._xlws.FILTER('2.WorkloadInventory'!A:A, '2.WorkloadInventory'!C:C = TableTypes8[[#This Row],[Resource Type]]))))} -> 4 | D16: {=IF(COUNTIF('4.ImpactedResourcesAnalysis'!C:C, TableTypes8[[#This Row],[Resource Type]])=0, 0, COUNTA(_xlfn.UNIQUE(_xlfn._xlws.FILTER('4.ImpactedResourcesAnalysis'!H:H, ('4.ImpactedResourcesAnalysis'!C:C=TableTypes8[[#This Row],[Resource Type]]) * ('4.ImpactedResourcesAnalysis'!H:H<>"Get ResourceID from Azure Portal")))))} -> 4 | E16: Yes | G16: =IF(OR(AND(TableTypes8[[#This Row],[Category]]="Support Requests", COUNTIFS('6.SupportRequestsAnalysis'!A:A, "<>Reviewed")=0),AND(TableTypes8[[#This Row],[Category]]="Platform Issues", COUNTIFS('5.PlatformIssuesAnalysis'!A:A, "<>Reviewed")=0),AND(TableTypes8[[#This Row],[Category]]="Impacted Resources", COUNTIFS('4.ImpactedResourcesAnalysis'!A:A, "<>Reviewed", '4.ImpactedResourcesAnalysis'!C:C, TableTypes8[[#This Row],[Resource Type]], '4.ImpactedResourcesAnalysis'!O:O, "<>Low")=0)), "Reviewed", "Pending") -> Reviewed
A17: Impacted Resources | B17: microsoft.operationalinsights/workspaces | C17: {=COUNTA(_xlfn.UNIQUE(_xlfn.VSTACK(_xlfn._xlws.FILTER('2.WorkloadInventory'!A:A, '2.WorkloadInventory'!C:C = TableTypes8[[#This Row],[Resource Type]]), _xlfn._xlws.FILTER('2.WorkloadInventory'!A:A, '2.WorkloadInventory'!C:C = TableTypes8[[#This Row],[Resource Type]]))))} -> 1 | D17: {=IF(COUNTIF('4.ImpactedResourcesAnalysis'!C:C, TableTypes8[[#This Row],[Resource Type]])=0, 0, COUNTA(_xlfn.UNIQUE(_xlfn._xlws.FILTER('4.ImpactedResourcesAnalysis'!H:H, ('4.ImpactedResourcesAnalysis'!C:C=TableTypes8[[#This Row],[Resource Type]]) * ('4.ImpactedResourcesAnalysis'!H:H<>"Get ResourceID from Azure Portal")))))} -> 1 | E17: Yes | G17: =IF(OR(AND(TableTypes8[[#This Row],[Category]]="Support Requests", COUNTIFS('6.SupportRequestsAnalysis'!A:A, "<>Reviewed")=0),AND(TableTypes8[[#This Row],[Category]]="Platform Issues", COUNTIFS('5.PlatformIssuesAnalysis'!A:A, "<>Reviewed")=0),AND(TableTypes8[[#This Row],[Category]]="Impacted Resources", COUNTIFS('4.ImpactedResourcesAnalysis'!A:A, "<>Reviewed", '4.ImpactedResourcesAnalysis'!C:C, TableTypes8[[#This Row],[Resource Type]], '4.ImpactedResourcesAnalysis'!O:O, "<>Low")=0)), "Reviewed", "Pending") -> Pending
A18: Impacted Resources | B18: Microsoft.Search/searchServices | C18: {=COUNTA(_xlfn.UNIQUE(_xlfn.VSTACK(_xlfn._xlws.FILTER('2.WorkloadInventory'!A:A, '2.WorkloadInventory'!C:C = TableTypes8[[#This Row],[Resource Type]]), _xlfn._xlws.FILTER('2.WorkloadInventory'!A:A, '2.WorkloadInventory'!C:C = TableTypes8[[#This Row],[Resource Type]]))))} -> 1 | D18: {=IF(COUNTIF('4.ImpactedResourcesAnalysis'!C:C, TableTypes8[[#This Row],[Resource Type]])=0, 0, COUNTA(_xlfn.UNIQUE(_xlfn._xlws.FILTER('4.ImpactedResourcesAnalysis'!H:H, ('4.ImpactedResourcesAnalysis'!C:C=TableTypes8[[#This Row],[Resource Type]]) * ('4.ImpactedResourcesAnalysis'!H:H<>"Get ResourceID from Azure Portal")))))} -> 1 | E18: Yes | G18: =IF(OR(AND(TableTypes8[[#This Row],[Category]]="Support Requests", COUNTIFS('6.SupportRequestsAnalysis'!A:A, "<>Reviewed")=0),AND(TableTypes8[[#This Row],[Category]]="Platform Issues", COUNTIFS('5.PlatformIssuesAnalysis'!A:A, "<>Reviewed")=0),AND(TableTypes8[[#This Row],[Category]]="Impacted Resources", COUNTIFS('4.ImpactedResourcesAnalysis'!A:A, "<>Reviewed", '4.ImpactedResourcesAnalysis'!C:C, TableTypes8[[#This Row],[Resource Type]], '4.ImpactedResourcesAnalysis'!O:O, "<>Low")=0)), "Reviewed", "Pending") -> Pending
A19: Impacted Resources | B19: Microsoft.Storage/storageAccounts | C19: {=COUNTA(_xlfn.UNIQUE(_xlfn.VSTACK(_xlfn._xlws.FILTER('2.WorkloadInventory'!A:A, '2.WorkloadInventory'!C:C = TableTypes8[[#This Row],[Resource Type]]), _xlfn._xlws.FILTER('2.WorkloadInventory'!A:A, '2.WorkloadInventory'!C:C = TableTypes8[[#This Row],[Resource Type]]))))} -> 3 | D19: {=IF(COUNTIF('4.ImpactedResourcesAnalysis'!C:C, TableTypes8[[#This Row],[Resource Type]])=0, 0, COUNTA(_xlfn.UNIQUE(_xlfn._xlws.FILTER('4.ImpactedResourcesAnalysis'!H:H, ('4.ImpactedResourcesAnalysis'!C:C=TableTypes8[[#This Row],[Resource Type]]) * ('4.ImpactedResourcesAnalysis'!H:H<>"Get ResourceID from Azure Portal")))))} -> 3 | E19: Yes | G19: =IF(OR(AND(TableTypes8[[#This Row],[Category]]="Support Requests", COUNTIFS('6.SupportRequestsAnalysis'!A:A, "<>Reviewed")=0),AND(TableTypes8[[#This Row],[Category]]="Platform Issues", COUNTIFS('5.PlatformIssuesAnalysis'!A:A, "<>Reviewed")=0),AND(TableTypes8[[#This Row],[Category]]="Impacted Resources", COUNTIFS('4.ImpactedResourcesAnalysis'!A:A, "<>Reviewed", '4.ImpactedResourcesAnalysis'!C:C, TableTypes8[[#This Row],[Resource Type]], '4.ImpactedResourcesAnalysis'!O:O, "<>Low")=0)), "Reviewed", "Pending") -> Reviewed
A20: Impacted Resources | B20: microsoft.web/serverfarms | C20: {=COUNTA(_xlfn.UNIQUE(_xlfn.VSTACK(_xlfn._xlws.FILTER('2.WorkloadInventory'!A:A, '2.WorkloadInventory'!C:C = TableTypes8[[#This Row],[Resource Type]]), _xlfn._xlws.FILTER('2.WorkloadInventory'!A:A, '2.WorkloadInventory'!C:C = TableTypes8[[#This Row],[Resource Type]]))))} -> 1 | D20: {=IF(COUNTIF('4.ImpactedResourcesAnalysis'!C:C, TableTypes8[[#This Row],[Resource Type]])=0, 0, COUNTA(_xlfn.UNIQUE(_xlfn._xlws.FILTER('4.ImpactedResourcesAnalysis'!H:H, ('4.ImpactedResourcesAnalysis'!C:C=TableTypes8[[#This Row],[Resource Type]]) * ('4.ImpactedResourcesAnalysis'!H:H<>"Get ResourceID from Azure Portal")))))} -> 1 | E20: Yes | G20: =IF(OR(AND(TableTypes8[[#This Row],[Category]]="Support Requests", COUNTIFS('6.SupportRequestsAnalysis'!A:A, "<>Reviewed")=0),AND(TableTypes8[[#This Row],[Category]]="Platform Issues", COUNTIFS('5.PlatformIssuesAnalysis'!A:A, "<>Reviewed")=0),AND(TableTypes8[[#This Row],[Category]]="Impacted Resources", COUNTIFS('4.ImpactedResourcesAnalysis'!A:A, "<>Reviewed", '4.ImpactedResourcesAnalysis'!C:C, TableTypes8[[#This Row],[Resource Type]], '4.ImpactedResourcesAnalysis'!O:O, "<>Low")=0)), "Reviewed", "Pending") -> Pending
A21: Impacted Resources | B21: Microsoft.Web/sites | C21: {=COUNTA(_xlfn.UNIQUE(_xlfn.VSTACK(_xlfn._xlws.FILTER('2.WorkloadInventory'!A:A, '2.WorkloadInventory'!C:C = TableTypes8[[#This Row],[Resource Type]]), _xlfn._xlws.FILTER('2.WorkloadInventory'!A:A, '2.WorkloadInventory'!C:C = TableTypes8[[#This Row],[Resource Type]]))))} -> 1 | D21: {=IF(COUNTIF('4.ImpactedResourcesAnalysis'!C:C, TableTypes8[[#This Row],[Resource Type]])=0, 0, COUNTA(_xlfn.UNIQUE(_xlfn._xlws.FILTER('4.ImpactedResourcesAnalysis'!H:H, ('4.ImpactedResourcesAnalysis'!C:C=TableTypes8[[#This Row],[Resource Type]]) * ('4.ImpactedResourcesAnalysis'!H:H<>"Get ResourceID from Azure Portal")))))} -> 2 | E21: Yes | G21: =IF(OR(AND(TableTypes8[[#This Row],[Category]]="Support Requests", COUNTIFS('6.SupportRequestsAnalysis'!A:A, "<>Reviewed")=0),AND(TableTypes8[[#This Row],[Category]]="Platform Issues", COUNTIFS('5.PlatformIssuesAnalysis'!A:A, "<>Reviewed")=0),AND(TableTypes8[[#This Row],[Category]]="Impacted Resources", COUNTIFS('4.ImpactedResourcesAnalysis'!A:A, "<>Reviewed", '4.ImpactedResourcesAnalysis'!C:C, TableTypes8[[#This Row],[Resource Type]], '4.ImpactedResourcesAnalysis'!O:O, "<>Low")=0)), "Reviewed", "Pending") -> Pending
A22: Support Requests | B22: N/A | C22: n/a | D22: n/a | E22: Yes | G22: Pending
A23: Platform Issues | B23: N/A | C23: n/a | D23: n/a | E23: Yes | G23: Pending

Sheet 4.ImpactedResourcesAnalysis
C4: Reviewed | D4: =COUNTIF(A:A,"Reviewed") -> 28
C5: Pending (High/Medium) | D5: =COUNTIFS(A:A,"<>Reviewed",A:A,"<>",O:O,"<>Low")-1 -> 42
C6: Pending (Low) | D6: =COUNTIFS(A:A,"<>Reviewed",A:A,"<>",O:O,"Low") -> 19
C7: Total | D7: =SUM(D4:D6) -> 89
D10: Resource information block | N10: Recommendation information block | X10: Additional information block
G11: Required | H11: Required | N11: Required | O11: Required | P11: Required | Q11: Required | R11: Required | S11: Required
A12: REQUIRED ACTIONS / REVIEW STATUS | B12: ValidationCategory | C12: Resource Type | D12: subscriptionId | E12: resourceGroup | F12: location | G12: name | H12: id | I12: custom1 | J12: custom2 | K12: custom3 | L12: custom4 | M12: custom5 | N12: Recommendation Title | O12: Impact | P12: Recommendation Control | Q12: Potential Benefit | R12: Learn More Link | S12: Long Description | T12: Guid | U12: Category | V12: Source | W12: WAF Pillar | X12: Platform Issue TrackingId | Y12: Retirement TrackingId | Z12: Support Request Number | AA12: Notes | AB12: checkName
A13: REQUIRED ACTIONS: Recommendation does not have automated validation._x000D_ This recommendation does not have automated validation. Since it cannot be validated automatically, follow these steps:_x000D_ 1. Review the Recommendation Title and Description to understand the recommendation. Use the "Read More" links for additional information._x000D_ 2. Open the Azure Portal and locate the potentially impacted resource using its Resource Name or ResourceId._x000D_ 3. Manually validate the resource._x000D_ 4. If the resource is not compliant with the recommendation, update this cell to "Reviewed"._x000D_ or_x000D_ 5. Delete this row if the resource is irrelevant or already compliant with the recommendation. | B13: Resource | C13: Microsoft.Web/sites | D13: 508d4c26-18a2-4b58-b83d-5535758910b0 | E13: scaa0 | F13: eastus2 | G13: app-scaa0-eus2-dev-zzhkrt | H13: /subscriptions/508d4c26-18a2-4b58-b83d-5535758910b0/resourceGroups/scaa0/providers/Microsoft.Web/sites/app-scaa0-eus2-dev-zzhkrt | N13: Enable diagnostics logging | O13: Low | P13: Monitoring And Alerting | Q13: Monitoring and Alerting | R13: https://learn.microsoft.com/azure/app-service/troubleshoot-diagnostic-logs | S13: Enabling diagnostics logging for your Azure App Service is crucial for monitoring and diagnostics, including both application logging and web server logging. | T13: 493f6079-3bb6-4a56-96ba-ab3248474cb1 | U13: Azure Service | V13: APRL | W13: Reliability
A14: REQUIRED ACTIONS: Recommendation does not have automated validation._x000D_ This recommendation does not have automated validation. Since it cannot be validated automatically, follow these steps:_x000D_ 1. Review the Recommendation Title and Description to understand the recommendation. Use the "Read More" links for additional information._x000D_ 2. Open the Azure Portal and locate the potentially impacted resource using its Resource Name or ResourceId._x000D_ 3. Manually validate the resource._x000D_ 4. If the resource is not compliant with the recommendation, update this cell to "Reviewed"._x000D_ or_x000D_ 5. Delete this row if the resource is irrelevant or already compliant with the recommendation. | B14: Resource | C14: Microsoft.Web/sites | D14: 508d4c26-18a2-4b58-b83d-5535758910b0 | E14: scaa0 | F14: eastus2 | G14: app-scaa0-eus2-dev-zzhkrt | H14: /subscriptions/508d4c26-18a2-4b58-b83d-5535758910b0/resourceGroups/scaa0/providers/Microsoft.Web/sites/app-scaa0-eus2-dev-zzhkrt | N14: Monitor Performance | O14: High | P14: Monitoring And Alerting | Q14: Real-time insights and issue diagnosis | R14: https://learn.microsoft.com/azure/application-insights/app-insights-overview | S14: Use Application Insights to monitor app performance and load behavior, offering real-time insights, issue diagnosis, and root-cause analysis. It supports ASP.NET, ASP.NET Core, Java, and Node.js on Azure App Service, now with built-in monitoring. | T14: a7e8bb3d-8ceb-442d-b26f-007cd63f9ffc | U14: Azure Service | V14: APRL | W14: Reliability
A15: REQUIRED ACTIONS: Recommendation does not have automated validation._x000D_ This recommendation does not have automated validation. Since it cannot be validated automatically, follow these steps:_x000D_ 1. Review the Recommendation Title and Description to understand the recommendation. Use the "Read More" links for additional information._x000D_ 2. Open the Azure Portal and locate the potentially impacted resource using its Resource Name or ResourceId._x000D_ 3. Manually validate the resource._x000D_ 4. If the resource is not compliant with the recommendation, update this cell to "Reviewed"._x000D_ or_x000D_ 5. Delete this row if the resource is irrelevant or already compliant with the recommendation. | B15: Resource | C15: Microsoft.Web/sites | D15: 508d4c26-18a2-4b58-b83d-5535758910b0 | E15: scaa0 | F15: eastus2 | G15: app-scaa0-eus2-dev-zzhkrt | H15: /subscriptions/508d4c26-18a2-4b58-b83d-5535758910b0/resourceGroups/scaa0/providers/Microsoft.Web/sites/app-scaa0-eus2-dev-zzhkrt | N15: Separate web apps from web APIs | O15: Low | P15: Scalability | Q15: Independent scaling, easier management | R15: https://learn.microsoft.com/azure/architecture/checklist/resiliency-per-service#app-service | S15: If your solution includes both a web front end and a web API, decomposing them into separate App Service apps facilitates solution decomposition by workload, allowing for independent scaling. Initially, you can deploy both in the same plan and separate them for independent scaling when necessary. | T15: 78a5c033-ff51-4332-8a71-83464c34494b | U15: Azure Service | V15: APRL | W15: Reliability
A16: REQUIRED ACTIONS: Recommendation does not have automated validation._x000D_ This recommendation does not have automated validation. Since it cannot be validated automatically, follow these steps:_x000D_ 1. Review the Recommendation Title and Description to understand the recommendation. Use the "Read More" links for additional information._x000D_ 2. Open the Azure Portal and locate the potentially impacted resource using its Resource Name or ResourceId._x000D_ 3. Manually validate the resource._x000D_ 4. If the resource is not compliant with the recommendation, update this cell to "Reviewed"._x000D_ or_x000D_ 5. Delete this row if the resource is irrelevant or already compliant with the recommendation. | B16: Resource | C16: Microsoft.Web/sites | D16: 508d4c26-18a2-4b58-b83d-5535758910b0 | E16: scaa0 | F16: eastus2 | G16: app-scaa0-eus2-dev-zzhkrt | H16: /subscriptions/508d4c26-18a2-4b58-b83d-5535758910b0/resourceGroups/scaa0/providers/Microsoft.Web/sites/app-scaa0-eus2-dev-zzhkrt | N16: Create a separate storage account for logs | O16: Medium | P16: Scalability | Q16: Improves app performance | R16: https://learn.microsoft.com/azure/architecture/checklist/resiliency-per-service#app-service | S16: Creating a separate storage account for logs and not using the same one for application data prevents logging activities from reducing application performance by ensuring that the resources dedicated to handling application data are not burdened by logging processes. | T16: 3f9ddb59-0bb3-4acb-9c9b-99aa1776f0ab | U16: Azure Service | V16: APRL | W16: Reliability
A17: Reviewed | B17: Resource | C17: Microsoft.Web/sites | D17: 508d4c26-18a2-4b58-b83d-5535758910b0 | E17: scaa0 | F17: eastus2 | G17: app-scaa0-eus2-dev-zzhkrt | H17: /subscriptions/508d4c26-18a2-4b58-b83d-5535758910b0/resourceGroups/scaa0/providers/Microsoft.Web/sites/app-scaa0-eus2-dev-zzhkrt | I17: AppSettings is not configured | N17: Store configuration as app settings for Web Sites | O17: Medium | P17: Other Best Practices | Q17: Enhanced reliability via automation | R17: https://learn.microsoft.com/azure/app-service-web/web-sites-configure | S17: Use app settings for configuration and define them in Resource Manager templates or via PowerShell to facilitate part of an automated deployment/update process for improved reliability. | T17: 0b80b67c-afbe-4988-ad58-a85a146b681e | U17: Azure Service | V17: APRL | W17: Reliability
A18: Reviewed | B18: Resource | C18: Microsoft.Web/sites | D18: 508d4c26-18a2-4b58-b83d-5535758910b0 | E18: scaa0 | F18: eastus2 | G18: app-scaa0-eus2-dev-zzhkrt | H18: /subscriptions/508d4c26-18a2-4b58-b83d-5535758910b0/resourceGroups/scaa0/providers/Microsoft.Web/sites/app-scaa0-eus2-dev-zzhkrt | I18: Healthcheckpath = not set | N18: Enable Health check for App Services | O18: High | P18: Other Best Practices | Q18: Enhanced reliability via automation | R18: https://learn.microsoft.com/azure/app-service/monitor-instances-health-check?tabs=dotnet#enable-health-check | S18: Use Health Check for production workloads. Health check increases your application's availability by rerouting requests away from unhealthy instances, and replacing instances if they remain unhealthy. The Health check path should check critical components of your application. | T18: fd049c28-ae6d-48f0-a641-cc3ba1a3fe1d | U18: Azure Service | V18: APRL | W18: Reliability
A19: REQUIRED ACTIONS: Recommendation does not have automated validation._x000D_ This recommendation does not have automated validation. Since it cannot be validated automatically, follow these steps:_x000D_ 1. Review the Recommendation Title and Description to understand the recommendation. Use the "Read More" links for additional information._x000D_ 2. Open the Azure Portal and locate the potentially impacted resource using its Resource Name or ResourceId._x000D_ 3. Manually validate the resource._x000D_ 4. If the resource is not compliant with the recommendation, update this cell to "Reviewed"._x000D_ or_x000D_ 5. Delete this row if the resource is irrelevant or already compliant with the recommendation. | B19: Resource | C19: Microsoft.Web/sites | D19: 508d4c26-18a2-4b58-b83d-5535758910b0 | E19: scaa0 | F19: eastus2 | G19: app-scaa0-eus2-dev-zzhkrt | H19: /subscriptions/508d4c26-18a2-4b58-b83d-5535758910b0/resourceGroups/scaa0/providers/Microsoft.Web/sites/app-scaa0-eus2-dev-zzhkrt | N19: No warmup trigger added to Function App | O19: Medium | P19: Monitoring And Alerting | Q19: Improved app availability | R19: https://learn.microsoft.com/azure/azure-functions/functions-bindings-warmup?tabs=in-process%2Cnodejs-v4&pivots=programming-language-csharp#trigger | S19: Add a warmup trigger to pre-load custom dependencies during the pre-warming process so that your functions are ready to start processing requests immediately. | T19: 52f368ee-1d77-4b34-92db-64be269642d0 | U19: Azure Service | V19: APRL | W19: Reliability
A20: REQUIRED ACTIONS: Recommendation does not have automated validation._x000D_ This recommendation does not have automated validation. Since it cannot be validated automatically, follow these steps:_x000D_ 1. Review the Recommendation Title and Description to understand the recommendation. Use the "Read More" links for additional information._x000D_ 2. Open the Azure Portal and locate the potentially impacted resource using its Resource Name or ResourceId._x000D_ 3. Manually validate the resource._x000D_ 4. If the resource is not compliant with the recommendation, update this cell to "Reviewed"._x000D_ or_x000D_ 5. Delete this row if the resource is irrelevant or already compliant with the recommendation. | B20: Resource | C20: Microsoft.Web/sites | D20: 508d4c26-18a2-4b58-b83d-5535758910b0 | E20: scaa0 | F20: eastus2 | G20: app-scaa0-eus2-dev-zzhkrt | H20: /subscriptions/508d4c26-18a2-4b58-b83d-5535758910b0/resourceGroups/scaa0/providers/Microsoft.Web/sites/app-scaa0-eus2-dev-zzhkrt | N20: Ensure unique hostid set for Function App | O20: Low | P20: Other Best Practices | Q20: Easier management | R20: https://learn.microsoft.com/azure/azure-resource-manager/management/resource-name-rules | S20: A host ID must be between 1 and 32 characters, contain only lowercase letters, numbers, and dashes, not start or end with a dash, and not contain consecutive dashes. The host ID value should be unique for all apps/slots you're running. | T20: 0b06a688-0dd6-4d73-9f72-6666ff853ca9 | U20: Azure Service | V20: APRL | W20: Reliability
A21: REQUIRED ACTIONS: Recommendation does not have automated validation._x000D_ This recommendation does not have automated validation. Since it cannot be validated automatically, follow these steps:_x000D_ 1. Review the Recommendation Title and Description to understand the recommendation. Use the "Read More" links for additional information._x000D_ 2. Open the Azure Portal and locate the potentially impacted resource using its Resource Name or ResourceId._x000D_ 3. Manually validate the resource._x000D_ 4. If the resource is not compliant with the recommendation, update this cell to "Reviewed"._x000D_ or_x000D_ 5. Delete this row if the resource is irrelevant or already compliant with the recommendation. | B21: Resource | C21: Microsoft.Web/sites | D21: 508d4c26-18a2-4b58-b83d-5535758910b0 | E21: scaa0 | F21: eastus2 | G21: app-scaa0-eus2-dev-zzhkrt | H21: /subscriptions/508d4c26-18a2-4b58-b83d-5535758910b0/resourceGroups/scaa0/providers/Microsoft.Web/sites/app-scaa0-eus2-dev-zzhkrt | N21: Ensure Function App runs a supported version | O21: Medium | P21: Other Best Practices | Q21: Better governance | R21: https://learn.microsoft.com/azure/azure-functions/migrate-version-3-version-4?tabs=net6-in-proc%2Cazure-cli%2Cwindows&pivots=programming-language-csharp | S21: Beginning on December 13, 2022, function apps running on versions 2.x and 3.x of the Azure Functions runtime have reached the end of life (EOL) of extended support. We highly recommend you migrating your function apps to version 4.x of the Functions runtime. | T21: c9a278b7-024b-454b-bd54-41587c512b74 | U21: Azure Service | V21: APRL | W21: Reliability
A22: REQUIRED ACTIONS: Recommendation does not have automated validation._x000D_ This recommendation does not have automated validation. Since it cannot be validated automatically, follow these steps:_x000D_ 1. Review the Recommendation Title and Description to understand the recommendation. Use the "Read More" links for additional information._x000D_ 2. Open the Azure Portal and locate the potentially impacted resource using its Resource Name or ResourceId._x000D_ 3. Manually validate the resource._x000D_ 4. If the resource is not compliant with the recommendation, update this cell to "Reviewed"._x000D_ or_x000D_ 5. Delete this row if the resource is irrelevant or already compliant with the recommendation. | B22: Resource | C22: Microsoft.Web/sites | D22: 508d4c26-18a2-4b58-b83d-5535758910b0 | E22: scaa0 | F22: eastus2 | G22: app-scaa0-eus2-dev-zzhkrt | H22: /subscriptions/508d4c26-18a2-4b58-b83d-5535758910b0/resourceGroups/scaa0/providers/Microsoft.Web/sites/app-scaa0-eus2-dev-zzhkrt | N22: Ensure FUNCTIONS_WORKER_RUNTIME is set properly | O22: Medium | P22: Other Best Practices | Q22: Better governance | R22: https://learn.microsoft.com/azure/azure-functions/functions-app-settings#functions_worker_runtime | S22: The FUNCTIONS_WORKER_RUNTIME setting in the Function App configuration should be set to the appropriate value based on the language you are using. This setting is used to determine the language worker that will be used to execute your functions. | T22: 7c608f46-46b2-4cc0-bbd6-1d457c16671c | U22: Azure Service | V22: APRL | W22: Reliability
A23: REQUIRED ACTIONS: Recommendation does not have automated validation._x000D_ This recommendation does not have automated validation. Since it cannot be validated automatically, follow these steps:_x000D_ 1. Review the Recommendation Title and Description to understand the recommendation. Use the "Read More" links for additional information._x000D_ 2. Open the Azure Portal and locate the potentially impacted resource using its Resource Name or ResourceId._x000D_ 3. Manually validate the resource._x000D_ 4. If the resource is not compliant with the recommendation, update this cell to "Reviewed"._x000D_ or_x000D_ 5. Delete this row if the resource is irrelevant or already compliant with the recommendation. | B23: Resource | C23: microsoft.web/serverfarms | D23: 508d4c26-18a2-4b58-b83d-5535758910b0 | E23: scaa0 | F23: eastus2 | G23: asp-scaa0-eus2-dev | H23: /subscriptions/508d4c26-18a2-4b58-b83d-5535758910b0/resourceGroups/scaa0/providers/Microsoft.Web/serverFarms/asp-scaa0-eus2-dev | N23: Create separate App Service plans for production and test | O23: High | P23: Other Best Practices | Q23: Protects prod performance; avoids test impact | R23: https://learn.microsoft.com/azure/architecture/checklist/resiliency-per-service#app-service | S23: It is strongly recommended to create separate App Service plans for production and test environments to avoid using slots within your production deployment for testing purposes. | T23: dbe3fd66-fb2a-9d46-b162-1791e21da236 | U23: Azure Service | V23: APRL | W23: Reliability
A24: REQUIRED ACTIONS: Recommendation does not have automated validation._x000D_ This recommendation does not have automated validation. Since it cannot be validated automatically, follow these steps:_x000D_ 1. Review the Recommendation Title and Description to understand the recommendation. Use the "Read More" links for additional information._x000D_ 2. Open the Azure Portal and locate the potentially impacted resource using its Resource Name or ResourceId._x000D_ 3. Manually validate the resource._x000D_ 4. If the resource is not compliant with the recommendation, update this cell to "Reviewed"._x000D_ or_x000D_ 5. Delete this row if the resource is irrelevant or already compliant with the recommendation. | B24: Resource | C24: microsoft.web/serverfarms | D24: 508d4c26-18a2-4b58-b83d-5535758910b0 | E24: scaa0 | F24: eastus2 | G24: asp-scaa0-eus2-dev | H24: /subscriptions/508d4c26-18a2-4b58-b83d-5535758910b0/resourceGroups/scaa0/providers/Microsoft.Web/serverFarms/asp-scaa0-eus2-dev | N24: Enable Autoscale/Automatic scaling to ensure adequate resources are available to service requests | O24: Medium | P24: Scalability | Q24: Optimizes resources for traffic | R24: https://learn.microsoft.com/azure/app-service/manage-automatic-scaling?tabs=azure-portal | S24: Enabling Autoscale/Automatic Scaling for your Azure App Service ensures sufficient resources for incoming requests. Autoscaling is rule-based, whereas Automatic Scaling, a newer feature, automatically adjusts resources based on HTTP traffic. | T24: 6320abf6-f917-1843-b2ae-4779c35985ae | U24: Azure Service | V24: APRL | W24: Reliability
A25: REQUIRED ACTIONS: Recommendation does not have automated validation._x000D_ This recommendation does not have automated validation. Since it cannot be validated automatically, follow these steps:_x000D_ 1. Review the Recommendation Title and Description to understand the recommendation. Use the "Read More" links for additional information._x000D_ 2. Open the Azure Portal and locate the potentially impacted resource using its Resource Name or ResourceId._x000D_ 3. Manually validate the resource._x000D_ 4. If the resource is not compliant with the recommendation, update this cell to "Reviewed"._x000D_ or_x000D_ 5. Delete this row if the resource is irrelevant or already compliant with the recommendation. | B25: Resource | C25: microsoft.cognitiveservices/accounts | D25: 508d4c26-18a2-4b58-b83d-5535758910b0 | E25: scaa0 | F25: eastus2 | G25: cog-scaa0-eus2-dev | H25: /subscriptions/508d4c26-18a2-4b58-b83d-5535758910b0/resourceGroups/scaa0/providers/Microsoft.CognitiveServices/accounts/cog-scaa0-eus2-dev | N25: Leverage Global provisioned deployment to ensure high and predictable throughput | O25: High | P25: High Availability | Q25: Low latency variance, high throughputs, business continuity | R25: https://learn.microsoft.com/azure/ai-services/openai/how-to/deployment-types#global-provisioned | S25: Global provisioned deployments provide reserved model processing capacity for high and predictable throughput using Azure global infrastructure. Suitable for applications requiring lower latency variance at large workload usage. Provides cost savings. | T25: 042c034e-2b85-4c1d-bf9a-65c75a6b43e9 | U25: Azure Service | V25: APRL | W25: Reliability
A26: REQUIRED ACTIONS: Recommendation does not have automated validation._x000D_ This recommendation does not have automated validation. Since it cannot be validated automatically, follow these steps:_x000D_ 1. Review the Recommendation Title and Description to understand the recommendation. Use the "Read More" links for additional information._x000D_ 2. Open the Azure Portal and locate the potentially impacted resource using its Resource Name or ResourceId._x000D_ 3. Manually validate the resource._x000D_ 4. If the resource is not compliant with the recommendation, update this cell to "Reviewed"._x000D_ or_x000D_ 5. Delete this row if the resource is irrelevant or already compliant with the recommendation. | B26: Resource | C26: microsoft.cognitiveservices/accounts | D26: 508d4c26-18a2-4b58-b83d-5535758910b0 | E26: scaa0 | F26: eastus2 | G26: oai-scaa0-eus2-dev | H26: /subscriptions/508d4c26-18a2-4b58-b83d-5535758910b0/resourceGroups/scaa0/providers/Microsoft.CognitiveServices/accounts/oai-scaa0-eus2-dev | N26: Leverage Global provisioned deployment to ensure high and predictable throughput | O26: High | P26: High Availability | Q26: Low latency variance, high throughputs, business continuity | R26: https://learn.microsoft.com/azure/ai-services/openai/how-to/deployment-types#global-provisioned | S26: Global provisioned deployments provide reserved model processing capacity for high and predictable throughput using Azure global infrastructure. Suitable for applications requiring lower latency variance at large workload usage. Provides cost savings. | T26: 042c034e-2b85-4c1d-bf9a-65c75a6b43e9 | U26: Azure Service | V26: APRL | W26: Reliability
A27: REQUIRED ACTIONS: Recommendation does not have automated validation._x000D_ This recommendation does not have automated validation. Since it cannot be validated automatically, follow these steps:_x000D_ 1. Review the Recommendation Title and Description to understand the recommendation. Use the "Read More" links for additional information._x000D_ 2. Open the Azure Portal and locate the potentially impacted resource using its Resource Name or ResourceId._x000D_ 3. Manually validate the resource._x000D_ 4. If the resource is not compliant with the recommendation, update this cell to "Reviewed"._x000D_ or_x000D_ 5. Delete this row if the resource is irrelevant or already compliant with the recommendation. | B27: Resource | C27: microsoft.cognitiveservices/accounts | D27: 508d4c26-18a2-4b58-b83d-5535758910b0 | E27: scaa0 | F27: eastus2 | G27: cog-scaa0-eus2-dev | H27: /subscriptions/508d4c26-18a2-4b58-b83d-5535758910b0/resourceGroups/scaa0/providers/Microsoft.CognitiveServices/accounts/cog-scaa0-eus2-dev | N27: Ensure PAYG AOAI models leverage Global Standard deployment | O27: High | P27: High Availability | Q27: Best model availability, business continuity | R27: https://learn.microsoft.com/azure/ai-services/openai/how-to/deployment-types#global-standard | S27: Global Standard leverages Azure's global infrastructure to route traffic to the best available data center for customer's real-time inference requests. It provides the highest default quota and eliminates the need to load balance across multiple resources. Optimized for low to medium volume usage. | T27: 081fc8a4-b2d9-405b-b351-334e621016f5 | U27: Azure Service | V27: APRL | W27: Reliability
A28: REQUIRED ACTIONS: Recommendation does not have automated validation._x000D_ This recommendation does not have automated validation. Since it cannot be validated automatically, follow these steps:_x000D_ 1. Review the Recommendation Title and Description to understand the recommendation. Use the "Read More" links for additional information._x000D_ 2. Open the Azure Portal and locate the potentially impacted resource using its Resource Name or ResourceId._x000D_ 3. Manually validate the resource._x000D_ 4. If the resource is not compliant with the recommendation, update this cell to "Reviewed"._x000D_ or_x000D_ 5. Delete this row if the resource is irrelevant or already compliant with the recommendation. | B28: Resource | C28: microsoft.cognitiveservices/accounts | D28: 508d4c26-18a2-4b58-b83d-5535758910b0 | E28: scaa0 | F28: eastus2 | G28: oai-scaa0-eus2-dev | H28: /subscriptions/508d4c26-18a2-4b58-b83d-5535758910b0/resourceGroups/scaa0/providers/Microsoft.CognitiveServices/accounts/oai-scaa0-eus2-dev | N28: Ensure PAYG AOAI models leverage Global Standard deployment | O28: High | P28: High Availability | Q28: Best model availability, business continuity | R28: https://learn.microsoft.com/azure/ai-services/openai/how-to/deployment-types#global-standard | S28: Global Standard leverages Azure's global infrastructure to route traffic to the best available data center for customer's real-time inference requests. It provides the highest default quota and eliminates the need to load balance across multiple resources. Optimized for low to medium volume usage. | T28: 081fc8a4-b2d9-405b-b351-334e621016f5 | U28: Azure Service | V28: APRL | W28: Reliability
A29: REQUIRED ACTIONS: Recommendation does not have automated validation._x000D_ This recommendation does not have automated validation. Since it cannot be validated automatically, follow these steps:_x000D_ 1. Review the Recommendation Title and Description to understand the recommendation. Use the "Read More" links for additional information._x000D_ 2. Open the Azure Portal and locate the potentially impacted resource using its Resource Name or ResourceId._x000D_ 3. Manually validate the resource._x000D_ 4. If the resource is not compliant with the recommendation, update this cell to "Reviewed"._x000D_ or_x000D_ 5. Delete this row if the resource is irrelevant or already compliant with the recommendation. | B29: Resource | C29: microsoft.cognitiveservices/accounts | D29: 508d4c26-18a2-4b58-b83d-5535758910b0 | E29: scaa0 | F29: eastus2 | G29: cog-scaa0-eus2-dev | H29: /subscriptions/508d4c26-18a2-4b58-b83d-5535758910b0/resourceGroups/scaa0/providers/Microsoft.CognitiveServices/accounts/cog-scaa0-eus2-dev | N29: Deploy a PAYG instance of the model with provisioned throughput to manage overflow effectively | O29: High | P29: High Availability | Q29: PAYG model balances cost and performance and helps scale | R29: https://learn.microsoft.com/azure/ai-services/openai/concepts/provisioned-throughput | S29: Provisioned Throughput offers pre-allocated capacity for consistent workloads, while Pay-as-You-Go charges for actual usage, ideal for variable workloads. During overflow, the Pay-as-You-Go instance manages excess load, ensuring service efficiency. | T29: 0c193899-da60-4a52-b4a0-77d75ac8c5c5 | U29: Azure Service | V29: APRL | W29: Reliability
A30: REQUIRED ACTIONS: Recommendation does not have automated validation._x000D_ This recommendation does not have automated validation. Since it cannot be validated automatically, follow these steps:_x000D_ 1. Review the Recommendation Title and Description to understand the recommendation. Use the "Read More" links for additional information._x000D_ 2. Open the Azure Portal and locate the potentially impacted resource using its Resource Name or ResourceId._x000D_ 3. Manually validate the resource._x000D_ 4. If the resource is not compliant with the recommendation, update this cell to "Reviewed"._x000D_ or_x000D_ 5. Delete this row if the resource is irrelevant or already compliant with the recommendation. | B30: Resource | C30: microsoft.cognitiveservices/accounts | D30: 508d4c26-18a2-4b58-b83d-5535758910b0 | E30: scaa0 | F30: eastus2 | G30: oai-scaa0-eus2-dev | H30: /subscriptions/508d4c26-18a2-4b58-b83d-5535758910b0/resourceGroups/scaa0/providers/Microsoft.CognitiveServices/accounts/oai-scaa0-eus2-dev | N30: Deploy a PAYG instance of the model with provisioned throughput to manage overflow effectively | O30: High | P30: High Availability | Q30: PAYG model balances cost and performance and helps scale | R30: https://learn.microsoft.com/azure/ai-services/openai/concepts/provisioned-throughput | S30: Provisioned Throughput offers pre-allocated capacity for consistent workloads, while Pay-as-You-Go charges for actual usage, ideal for variable workloads. During overflow, the Pay-as-You-Go instance manages excess load, ensuring service efficiency. | T30: 0c193899-da60-4a52-b4a0-77d75ac8c5c5 | U30: Azure Service | V30: APRL | W30: Reliability
... A40: REQUIRED ACTIONS: Recommendation does not have automated validation._x000D_ This recommendation does not have automated validation. Since it cannot be validated automatically, follow these steps:_x000D_ 1. Review the Recommendation Title and Description to understand the recommendation. Use the "Read More" links for additional information._x000D_ 2. Open the Azure Portal and locate the potentially impacted resource using its Resource Name or ResourceId._x000D_ 3. Manually validate the resource._x000D_ 4. If the resource is not compliant with the recommendation, update this cell to "Reviewed"._x000D_ or_x000D_ 5. Delete this row if the resource is irrelevant or already compliant with the recommendation. | B40: Resource | C40: microsoft.operationalinsights/workspaces | D40: 508d4c26-18a2-4b58-b83d-5535758910b0 | E40: monitoring | F40: eastus | G40: monitoring-law | H40: /subscriptions/508d4c26-18a2-4b58-b83d-5535758910b0/resourceGroups/monitoring/providers/Microsoft.OperationalInsights/workspaces/monitoring-law | N40: Create a health status alert rule for your Log Analytics workspace | O40: Low | P40: Monitoring And Alerting | Q40: Early alert for workspace failure | R40: https://learn.microsoft.com/azure/azure-monitor/logs/log-analytics-workspace-health | S40: A health status alert will proactively notify you if a workspace becomes unavailable because of a datacenter or regional failure. | T40: 4b77191c-cc3c-8c4e-844b-0f56d0927890 | U40: Azure Service | V40: APRL | W40: Reliability
A41: Reviewed | B41: Resource | C41: Microsoft.Storage/storageAccounts | D41: 508d4c26-18a2-4b58-b83d-5535758910b0 | E41: mcapsgovernance | F41: westus2 | G41: mcapsb83d5535758910b0 | H41: /subscriptions/508d4c26-18a2-4b58-b83d-5535758910b0/resourceGroups/McapsGovernance/providers/Microsoft.Storage/storageAccounts/mcapsb83d5535758910b0 | I41: sku: Standard_LRS | N41: Ensure that storage accounts are zone or region redundant | O41: High | P41: High Availability | Q41: High availability and durability for storage | R41: https://learn.microsoft.com/azure/storage/common/storage-redundancy | S41: Redundancy ensures storage accounts meet availability and durability targets amidst failures, weighing lower costs against higher availability. Locally redundant storage offers the least durability at the lowest cost. | T41: e6c7e1cc-2f47-264d-aa50-1da421314472 | U41: Azure Service | V41: APRL | W41: Reliability
A42: Reviewed | B42: Resource | C42: Microsoft.Storage/storageAccounts | D42: 508d4c26-18a2-4b58-b83d-5535758910b0 | E42: monitoring | F42: eastus | G42: pauharritest0sa | H42: /subscriptions/508d4c26-18a2-4b58-b83d-5535758910b0/resourceGroups/monitoring/providers/Microsoft.Storage/storageAccounts/pauharritest0sa | I42: sku: Standard_LRS | N42: Ensure that storage accounts are zone or region redundant | O42: High | P42: High Availability | Q42: High availability and durability for storage | R42: https://learn.microsoft.com/azure/storage/common/storage-redundancy | S42: Redundancy ensures storage accounts meet availability and durability targets amidst failures, weighing lower costs against higher availability. Locally redundant storage offers the least durability at the lowest cost. | T42: e6c7e1cc-2f47-264d-aa50-1da421314472 | U42: Azure Service | V42: APRL | W42: Reliability
A43: Reviewed | B43: Resource | C43: Microsoft.Storage/storageAccounts | D43: 508d4c26-18a2-4b58-b83d-5535758910b0 | E43: scaa0 | F43: eastus2 | G43: stscaa0eus2devzzhk | H43: /subscriptions/508d4c26-18a2-4b58-b83d-5535758910b0/resourceGroups/scaa0/providers/Microsoft.Storage/storageAccounts/stscaa0eus2devzzhk | I43: sku: Standard_LRS | N43: Ensure that storage accounts are zone or region redundant | O43: High | P43: High Availability | Q43: High availability and durability for storage | R43: https://learn.microsoft.com/azure/storage/common/storage-redundancy | S43: Redundancy ensures storage accounts meet availability and durability targets amidst failures, weighing lower costs against higher availability. Locally redundant storage offers the least durability at the lowest cost. | T43: e6c7e1cc-2f47-264d-aa50-1da421314472 | U43: Azure Service | V43: APRL | W43: Reliability
A44: REQUIRED ACTIONS: Recommendation does not have automated validation._x000D_ This recommendation does not have automated validation. Since it cannot be validated automatically, follow these steps:_x000D_ 1. Review the Recommendation Title and Description to understand the recommendation. Use the "Read More" links for additional information._x000D_ 2. Open the Azure Portal and locate the potentially impacted resource using its Resource Name or ResourceId._x000D_ 3. Manually validate the resource._x000D_ 4. If the resource is not compliant with the recommendation, update this cell to "Reviewed"._x000D_ or_x000D_ 5. Delete this row if the resource is irrelevant or already compliant with the recommendation. | B44: Resource | C44: Microsoft.Storage/storageAccounts | D44: 508d4c26-18a2-4b58-b83d-5535758910b0 | E44: scaa0 | F44: eastus2 | G44: stscaa0eus2devzzhk | H44: /subscriptions/508d4c26-18a2-4b58-b83d-5535758910b0/resourceGroups/scaa0/providers/Microsoft.Storage/storageAccounts/stscaa0eus2devzzhk | N44: Enable versioning for accidental modification and keep the number of versions below 1000 | O44: Low | P44: Disaster Recovery | Q44: Recover data, manage latency | R44: https://learn.microsoft.com/azure/storage/blobs/versioning-overview | S44: Consider enabling versioning for Azure Storage Accounts to recover from accidental modifications or deletions and manage blob operation latency. Microsoft advises maintaining fewer than 1000 versions per blob to optimize performance. Lifecycle management can help delete old versions automatically. | T44: 8ebda7c0-e0e1-ed45-af59-2d7ea9a1c05d | U44: Azure Service | V44: APRL | W44: Reliability
A45: REQUIRED ACTIONS: Recommendation does not have automated validation._x000D_ This recommendation does not have automated validation. Since it cannot be validated automatically, follow these steps:_x000D_ 1. Review the Recommendation Title and Description to understand the recommendation. Use the "Read More" links for additional information._x000D_ 2. Open the Azure Portal and locate the potentially impacted resource using its Resource Name or ResourceId._x000D_ 3. Manually validate the resource._x000D_ 4. If the resource is not compliant with the recommendation, update this cell to "Reviewed"._x000D_ or_x000D_ 5. Delete this row if the resource is irrelevant or already compliant with the recommendation. | B45: Resource | C45: Microsoft.Storage/storageAccounts | D45: 508d4c26-18a2-4b58-b83d-5535758910b0 | E45: monitoring | F45: eastus | G45: pauharritest0sa | H45: /subscriptions/508d4c26-18a2-4b58-b83d-5535758910b0/resourceGroups/monitoring/providers/Microsoft.Storage/storageAccounts/pauharritest0sa | N45: Enable versioning for accidental modification and keep the number of versions below 1000 | O45: Low | P45: Disaster Recovery | Q45: Recover data, manage latency | R45: https://learn.microsoft.com/azure/storage/blobs/versioning-overview | S45: Consider enabling versioning for Azure Storage Accounts to recover from accidental modifications or deletions and manage blob operation latency. Microsoft advises maintaining fewer than 1000 versions per blob to optimize performance. Lifecycle management can help delete old versions automatically. | T45: 8ebda7c0-e0e1-ed45-af59-2d7ea9a1c05d | U45: Azure Service | V45: APRL | W45: Reliability
